<?xml version='1.0' encoding='utf-8'?>
<robot name="walker_astron_v1_wf">
  <mujoco>
    <compiler meshdir="../meshes/" balanceinertia="false" discardvisual="false" autolimits="true" inertiafromgeom="false" convexhull="false" boundmass="0.0001" usethread="true" />
  </mujoco>
  <link name="base_link">
    <inertial>
      <origin rpy="0 0 0" xyz="-0.00060742 0 -0.00390464" />
      <mass value="5.32923152" />
      <inertia ixx="0.02561815" ixy="3.016E-05" ixz="-1.012E-05" iyy="0.01751097" iyz="-2.5E-07" izz="0.02397466" />
    </inertial>
    <visual>
      <origin rpy="0 0 0" xyz="0 0 0" />
      <geometry>
        <mesh filename="../meshes/base_link.STL" />
      </geometry>
      <material name="">
        <color rgba="0.627450980392157 0.627450980392157 0.627450980392157 1" />
      </material>
    </visual>
    <collision>
      <origin xyz="0 0 0.02" rpy="0 0 0" />
      <geometry>
        <box size="0.14 0.16 0.15" />
      </geometry>
    </collision>
  </link>
  <link name="waist_yaw_link">
    <inertial>
      <origin rpy="0 0 0" xyz="0.00270178 -0.00088235 0.03695265" />
      <mass value="2.06130216" />
      <inertia ixx="0.00455692" ixy="2.339E-05" ixz="-0.0004179" iyy="0.00399271" iyz="9.219E-05" izz="0.00564475" />
    </inertial>
    <visual>
      <origin rpy="0 0 0" xyz="0 0 0" />
      <geometry>
        <mesh filename="../meshes/waist_yaw_link.STL" />
      </geometry>
      <material name="">
        <color rgba="0.490196078431373 0.76078431372549 0.223529411764706 1" />
      </material>
    </visual>
  </link>
  <joint name="waist_yaw_joint" type="revolute">
    <origin rpy="0 0 0" xyz="0 0 0.0766405733000631" />
    <parent link="base_link" />
    <child link="waist_yaw_link" />
    <axis xyz="0 0 1" />
    <limit effort="63" lower="-2.792" upper="2.792" velocity="10.47" />
  </joint>
  <link name="waist_pitch_link">
    <inertial>
      <origin rpy="0 0 0" xyz="-0.00141152 -0.00378014 -1.015E-05" />
      <mass value="1.56616016" />
      <inertia ixx="0.00193458" ixy="4.94E-06" ixz="-2.31E-06" iyy="0.00149086" iyz="1.11E-06" izz="0.0020082" />
    </inertial>
    <visual>
      <origin rpy="0 0 0" xyz="0 0 0" />
      <geometry>
        <mesh filename="../meshes/waist_pitch_link.STL" />
      </geometry>
      <material name="">
        <color rgba="0.898039215686275 0.917647058823529 0.929411764705882 1" />
      </material>
    </visual>
  </link>
  <joint name="waist_pitch_joint" type="revolute">
    <origin rpy="0 0 0" xyz="0.0399999999999999 0 0.1155" />
    <parent link="waist_yaw_link" />
    <child link="waist_pitch_link" />
    <axis xyz="0 1 0" />
    <limit effort="165" lower="-0.017" upper="1.221" velocity="8.9" />
  </joint>
  <link name="waist_roll_link">
    <inertial>
      <origin rpy="0 0 0" xyz="0.0153246 0.00010908 0.15067891"/>
      <mass value="13.34004282" />
      <inertia ixx="0.14820786" ixy="-0.0001414" ixz="-0.00914777" iyy="0.12699244" iyz="0.00012313" izz="0.07921235" />
    </inertial>
    <visual>
      <origin rpy="0 0 0" xyz="0 0 0" />
      <geometry>
        <mesh filename="../meshes/waist_roll_link.STL" />
      </geometry>
      <material name="">
        <color rgba="1 1 1 1" />
      </material>
    </visual>
    <collision>
      <origin xyz="0.0115 0 0.13" rpy="0 0 0" />
      <geometry>
        <box size="0.18 0.2 0.28" />
      </geometry>
    </collision>
  </link>
  <joint name="waist_roll_joint" type="revolute">
    <origin rpy="0 0 0" xyz="-0.0515000000005501 0 0" />
    <parent link="waist_pitch_link" />
    <child link="waist_roll_link" />
    <axis xyz="1 0 0" />
    <limit effort="110" lower="-0.75" upper="0.75" velocity="10.47" />
  </joint>
  <link name="torso_link">
    <inertial>
      <origin rpy="0 0 0" xyz="0 0 0" />
      <mass value="0.0001" />
      <inertia ixx="1e-10" ixy="0" ixz="0" iyy="1e-10" iyz="0" izz="1e-10" />
    </inertial>
  </link>
  <joint name="torso_waist_joint" type="fixed">
    <origin rpy="0 0 0" xyz="0.0115000000000002 0 0.247778898928156" />
    <parent link="waist_roll_link" />
    <child link="torso_link" />
    <axis xyz="0 0 1" />
  </joint>
  <joint name="body_imu_joint" type="fixed">
    <origin rpy="0.0 0.0 -1.5707963267948966" xyz="0.0 0.0 0.0" />
    <parent link="base_link" />
    <child link="body_imu" />
  </joint>
  <link name="body_imu">
    <inertial>
      <mass value="0.0001" />
      <origin rpy="0 0 0" xyz="0 0 0" />
      <inertia ixx="1e-10" ixy="0" ixz="0" iyy="1e-10" iyz="0" izz="1e-10" />
    </inertial>
    <visual>
      <origin rpy="0 0 0" xyz="0 0 0" />
      <geometry>
        <box size="0.015 0.015 0.004" />
      </geometry>
    </visual>
    <material name="orange">
      <color rgba="255 108 10 255" />
    </material>
  </link>
  <imu_sensor name="body_imu">
    <parent link="base_link" />
    <origin rpy="0.0 0.0 -1.5707963267948966" xyz="0.0 0.0 0.0" />
  </imu_sensor>
  <gps_sensor name="body_gps">
    <parent link="base_link" />
    <origin rpy="0.0 0.0 0.0" xyz="0.0 0.0 0.0" />
  </gps_sensor>
  <link name="head_base_link">
    <inertial>
      <origin rpy="0 0 0" xyz="0 0 0" />
      <mass value="0.0001" />
      <inertia ixx="1e-10" ixy="0" ixz="0" iyy="1e-10" iyz="0" izz="1e-10" />
    </inertial>
  </link>
  <joint name="head_base_joint" type="fixed">
    <origin rpy="0 0 0" xyz="0.0 0 0.09527110107" />
    <parent link="torso_link" />
    <child link="head_base_link" />
    <axis xyz="0 0 1" />
  </joint>
  <link name="head_yaw_link">
    <inertial>
      <origin rpy="0 0 0" xyz="-0.00204647 0.00017996 -0.0311295" />
      <mass value="0.24151544" />
      <inertia ixx="0.00010433" ixy="2.2E-07" ixz="1.04E-06" iyy="9.811E-05" iyz="-8E-07" izz="8.868E-05" />
    </inertial>
    <visual>
      <origin rpy="0 0 0" xyz="0 0 0" />
      <geometry>
        <mesh filename="../meshes/head_yaw_link.STL" />
      </geometry>
      <material name="">
        <color rgba="1 0.674509803921569 0.309803921568627 1" />
      </material>
    </visual>
    <collision>
      <origin xyz="0 0 0.1" rpy="0 0 0" />
      <geometry>
        <sphere radius="0.1" />
      </geometry>
    </collision>
  </link>
  <joint name="head_yaw_joint" type="fixed">
    <origin rpy="0 0 0" xyz="0 0 0" />
    <parent link="head_base_link" />
    <child link="head_yaw_link" />
    <axis xyz="0 0 1" />
    <limit effort="4.5" lower="-1.658" upper="1.658" velocity="5.24" />
  </joint>
  <link name="head_pitch_link">
    <inertial>
      <origin rpy="0 0 0" xyz="0.02647525 0.00053943 0.05930006" />
      <mass value="1.13856043" />
      <inertia ixx="0.00517136" ixy="1.895E-05" ixz="-0.00081881" iyy="0.00598944" iyz="4.349E-05" izz="0.00326749" />
    </inertial>
    <visual>
      <origin rpy="0 0 0" xyz="0 0 0" />
      <geometry>
        <mesh filename="../meshes/head_pitch_link.STL" />
      </geometry>
      <material name="">
        <color rgba="0.698039215686274 0.698039215686274 0.698039215686274 1" />
      </material>
    </visual>
  </link>
  <joint name="head_pitch_joint" type="fixed">
    <origin rpy="0 0 0" xyz="0 0 0.0264999999999996" />
    <parent link="head_yaw_link" />
    <child link="head_pitch_link" />
    <axis xyz="0 1 0" />
    <limit effort="4.5" lower="-0.523" upper="0.785" velocity="5.24" />
  </joint>
  <joint name="head_imu_joint" type="fixed">
    <origin rpy="0.0 0.0 -1.5707963267948966" xyz="0.0 0.0 0.0" />
    <parent link="head_pitch_link" />
    <child link="head_imu" />
  </joint>
  <link name="head_imu">
    <inertial>
      <mass value="0.0001" />
      <origin rpy="0 0 0" xyz="0 0 0" />
      <inertia ixx="1e-10" ixy="0" ixz="0" iyy="1e-10" iyz="0" izz="1e-10" />
    </inertial>
    <visual>
      <origin rpy="0 0 0" xyz="0 0 0" />
      <geometry>
        <box size="0.015 0.015 0.004" />
      </geometry>
    </visual>
    <material name="orange">
      <color rgba="255 108 10 255" />
    </material>
  </link>
  <imu_sensor name="head_imu">
    <parent link="head_pitch_link" />
    <origin rpy="0.0 0.0 -1.5707963267948966" xyz="0.0 0.0 0.0" />
  </imu_sensor>
  <link name="L_hip_pitch_link">
    <inertial>
      <origin rpy="0 0 0" xyz="0.0048541 0.05006963 -0.01502711" />
      <mass value="1.65568528" />
      <inertia ixx="0.00241952" ixy="-3.402E-05" ixz="2.351E-05" iyy="0.00281444" iyz="0.00017664" izz="0.00267135" />
    </inertial>
    <visual>
      <origin rpy="0 0 0" xyz="0 0 0" />
      <geometry>
        <mesh filename="../meshes/L_hip_pitch_link.STL" />
      </geometry>
      <material name="">
        <color rgba="0.196078431372549 0.196078431372549 0.196078431372549 1" />
      </material>
    </visual>
  </link>
  <joint name="L_hip_pitch_joint" type="revolute">
    <origin rpy="-0.2618 0 0" xyz="0 0.073499 -0.019694" />
    <parent link="base_link" />
    <child link="L_hip_pitch_link" />
    <axis xyz="0 1 0" />
    <limit effort="210" lower="-2.98" upper="2.53" velocity="10.47" />
  </joint>
  <link name="L_hip_roll_link">
    <inertial>
      <origin rpy="0 0 0" xyz="0.00120874 0.00203626 -0.0330367" />
      <mass value="0.51480778" />
      <inertia ixx="0.00068355" ixy="1.85E-06" ixz="-2.72E-05" iyy="0.00158828" iyz="-1.21E-06" izz="0.00152555" />
    </inertial>
    <visual>
      <origin rpy="0 0 0" xyz="0 0 0" />
      <geometry>
        <mesh filename="../meshes/L_hip_roll_link.STL" />
      </geometry>
      <material name="">
        <color rgba="0.698039215686274 0.698039215686274 0.698039215686274 1" />
      </material>
    </visual>
  </link>
  <joint name="L_hip_roll_joint" type="revolute">
    <origin rpy="0.261799387799153 0 0" xyz="0 0.0535794918034543 -0.0199999995489613" />
    <parent link="L_hip_pitch_link" />
    <child link="L_hip_roll_link" />
    <axis xyz="1 0 0" />
    <limit effort="165" lower="-0.314" upper="2.059" velocity="8.9" />
  </joint>
  <link name="L_hip_yaw_link">
    <inertial>
      <origin rpy="0 0 0" xyz="-0.00120768 -0.00740878 -0.12389527" />
      <mass value="5.13192556" />
      <inertia ixx="0.04241863" ixy="8.24E-05" ixz="-0.00142152" iyy="0.04461162" iyz="-0.00037262" izz="0.01097702" />
    </inertial>
    <visual>
      <origin rpy="0 0 0" xyz="0 0 0" />
      <geometry>
        <mesh filename="../meshes/L_hip_yaw_link.STL" />
      </geometry>
      <material name="">
        <color rgba="0.698039215686274 0.698039215686274 0.698039215686274 1" />
      </material>
    </visual>
    <collision>
      <origin xyz="0 0 -0.19" rpy="0 0 0" />
      <geometry>
        <cylinder length="0.26" radius="0.06" />
      </geometry>
    </collision>
  </link>
  <joint name="L_hip_yaw_joint" type="revolute">
    <origin rpy="0 0 0" xyz="0 0 -0.0621000000000043" />
    <parent link="L_hip_roll_link" />
    <child link="L_hip_yaw_link" />
    <axis xyz="0 0 1" />
    <limit effort="110" lower="-2.146" upper="3.246" velocity="10.47" />
  </joint>
  <link name="L_knee_pitch_link">
    <inertial>
      <origin rpy="0 0 0" xyz="0.00270804 3.653E-05 -0.16040743" />
      <mass value="3.32222379" />
      <inertia ixx="0.03667868" ixy="-7.25E-06" ixz="-0.00131399" iyy="0.03696149" iyz="-0.00015599" izz="0.00351475" />
    </inertial>
    <visual>
      <origin rpy="0 0 0" xyz="0 0 0" />
      <geometry>
        <mesh filename="../meshes/L_knee_pitch_link.STL" />
      </geometry>
      <material name="">
        <color rgba="0.792156862745098 0.819607843137255 0.933333333333333 1" />
      </material>
    </visual>
    <collision>
      <origin xyz="0 0 -0.245" rpy="0 0 0" />
      <geometry>
        <cylinder length="0.21" radius="0.05" />
      </geometry>
    </collision>
  </link>
  <joint name="L_knee_pitch_joint" type="revolute">
    <origin rpy="0 0 0" xyz="-0.0349999999999581 0 -0.317899997262446" />
    <parent link="L_hip_yaw_link" />
    <child link="L_knee_pitch_link" />
    <axis xyz="0 1 0" />
    <limit effort="210" lower="0.09" upper="2.478" velocity="10.47" />
  </joint>
  <link name="L_ankle_pitch_link">
    <inertial>
      <origin rpy="0 0 0" xyz="-0.00012374 -0.00221434 -0.0057231" />
      <mass value="0.11058391" />
      <inertia ixx="2.571E-05" ixy="3E-08" ixz="-8E-08" iyy="3.443E-05" iyz="1.4E-06" izz="4.678E-05" />
    </inertial>
    <visual>
      <origin rpy="0 0 0" xyz="0 0 0" />
      <geometry>
        <mesh filename="../meshes/L_ankle_pitch_link.STL" />
      </geometry>
      <material name="">
        <color rgba="0.627450980392157 0.627450980392157 0.627450980392157 1" />
      </material>
    </visual>
  </link>
  <joint name="L_ankle_pitch_joint" type="revolute">
    <origin rpy="0 0 0" xyz="0 0 -0.409999999999987" />
    <parent link="L_knee_pitch_link" />
    <child link="L_ankle_pitch_link" />
    <axis xyz="0 1 0" />
    <limit effort="60" lower="-1.012" upper="0.488" velocity="12.57" />
  </joint>
  <link name="L_ankle_roll_link">
    <inertial>
      <origin rpy="0 0 0" xyz="0.03406324 2.02E-06 -0.020996" />
      <mass value="0.82687057" />
      <inertia ixx="0.00099158" ixy="-1.9E-07" ixz="0.0002988" iyy="0.00442435" iyz="-2E-08" izz="0.00489724" />
    </inertial>
    <visual>
      <origin rpy="0 0 0" xyz="0 0 0" />
      <geometry>
        <mesh filename="../meshes/L_ankle_roll_link.STL" />
      </geometry>
      <material name="">
        <color rgba="0.698039215686274 0.698039215686274 0.698039215686274 1" />
      </material>
    </visual>
    <collision>
      <origin xyz="0.05 0 -0.035" rpy="0 0 0" />
      <geometry>
        <box size="0.26 0.11 0.03" />
      </geometry>
    </collision>
  </link>
  <joint name="L_ankle_roll_joint" type="revolute">
    <origin rpy="0 0 0" xyz="0 0 -0.012" />
    <parent link="L_ankle_pitch_link" />
    <child link="L_ankle_roll_link" />
    <axis xyz="1 0 0" />
    <limit effort="60" lower="-0.401" upper="0.401" velocity="12.57" />
  </joint>
  <joint name="L_foot_ft_joint" type="fixed">
    <origin rpy="0 0 0" xyz="0 0 0" />
    <parent link="L_ankle_roll_link" />
    <child link="L_foot_ft_link" />
  </joint>
  <link name="L_foot_ft_link">
    <inertial>
      <mass value="0.00005" />
      <origin rpy="0 0 0" xyz="0 0 0" />
      <inertia ixx="5e-11" ixy="0" ixz="0" iyy="5e-11" iyz="0" izz="1e-10" />
    </inertial>
    <visual>
      <origin rpy="0 0 0" xyz="0 0 0" />
      <geometry>
        <cylinder length="0.01" radius="0.01" />
      </geometry>
    </visual>
    <material name="orange">
      <color rgba="255 108 10 255" />
    </material>
  </link>
  <ft_sensor name="L_foot_ft">
    <parent link="L_ankle_roll_link" />
    <origin rpy="0 0 0" xyz="0 0 0" />
  </ft_sensor>
  <link name="R_hip_pitch_link">
    <inertial>
      <origin rpy="0 0 0" xyz="0.0062436 -0.05042619 -0.01471604" />
      <mass value="1.65592419" />
      <inertia ixx="0.00242058" ixy="1.359E-05" ixz="4.82E-05" iyy="0.00275017" iyz="-0.0001869" izz="0.00261347" />
    </inertial>
    <visual>
      <origin rpy="0 0 0" xyz="0 0 0" />
      <geometry>
        <mesh filename="../meshes/R_hip_pitch_link.STL" />
      </geometry>
      <material name="">
        <color rgba="0.196078431372549 0.196078431372549 0.196078431372549 1" />
      </material>
    </visual>
  </link>
  <joint name="R_hip_pitch_joint" type="revolute">
    <origin rpy="0.261799387799121 0 0" xyz="0 -0.073422566263531 -0.0196735173365314" />
    <parent link="base_link" />
    <child link="R_hip_pitch_link" />
    <axis xyz="0 1 0" />
    <limit effort="210" lower="-2.98" upper="2.53" velocity="10.47" />
  </joint>
  <link name="R_hip_roll_link">
    <inertial>
      <origin rpy="0 0 0" xyz="0.00120761 -0.00204745 -0.033039" />
      <mass value="0.51480826" />
      <inertia ixx="0.00068354" ixy="-2.15E-06" ixz="-2.723E-05" iyy="0.00158816" iyz="1.2E-06" izz="0.00152554" />
    </inertial>
    <visual>
      <origin rpy="0 0 0" xyz="0 0 0" />
      <geometry>
        <mesh filename="../meshes/R_hip_roll_link.STL" />
      </geometry>
      <material name="">
        <color rgba="0.698039215686274 0.698039215686274 0.698039215686274 1" />
      </material>
    </visual>
  </link>
  <joint name="R_hip_roll_joint" type="revolute">
    <origin rpy="-0.2618 0 0" xyz="0 -0.053579 -0.02" />
    <parent link="R_hip_pitch_link" />
    <child link="R_hip_roll_link" />
    <axis xyz="1 0 0" />
    <limit effort="165" lower="-2.059" upper="0.314" velocity="8.9" />
  </joint>
  <link name="R_hip_yaw_link">
    <inertial>
      <origin rpy="0 0 0" xyz="-0.00120109 0.00740989 -0.12388792" />
      <mass value="5.13154726" />
      <inertia ixx="0.04242003" ixy="-9.387E-05" ixz="-0.00132247" iyy="0.04461121" iyz="0.00037314" izz="0.01097485" />
    </inertial>
    <visual>
      <origin rpy="0 0 0" xyz="0 0 0" />
      <geometry>
        <mesh filename="../meshes/R_hip_yaw_link.STL" />
      </geometry>
      <material name="">
        <color rgba="0.698039215686274 0.698039215686274 0.698039215686274 1" />
      </material>
    </visual>
    <collision>
      <origin xyz="0 0 -0.19" rpy="0 0 0" />
      <geometry>
        <cylinder length="0.26" radius="0.06" />
      </geometry>
    </collision>
  </link>
  <joint name="R_hip_yaw_joint" type="revolute">
    <origin rpy="0 0 0" xyz="0 0 -0.0621" />
    <parent link="R_hip_roll_link" />
    <child link="R_hip_yaw_link" />
    <axis xyz="0 0 1" />
    <limit effort="110" lower="-3.246" upper="2.146" velocity="10.47" />
  </joint>
  <link name="R_knee_pitch_link">
    <inertial>
      <origin rpy="0 0 0" xyz="0.00271353 -0.00017413 -0.1604776" />
      <mass value="3.32311625" />
      <inertia ixx="0.03667916" ixy="2.614E-05" ixz="-0.00129682" iyy="0.03697352" iyz="0.00015974" izz="0.00350144" />
    </inertial>
    <visual>
      <origin rpy="0 0 0" xyz="0 0 0" />
      <geometry>
        <mesh filename="../meshes/R_knee_pitch_link.STL" />
      </geometry>
      <material name="">
        <color rgba="0.792156862745098 0.819607843137255 0.933333333333333 1" />
      </material>
    </visual>
    <collision>
      <origin xyz="0 0 -0.245" rpy="0 0 0" />
      <geometry>
        <cylinder length="0.21" radius="0.05" />
      </geometry>
    </collision>
  </link>
  <joint name="R_knee_pitch_joint" type="revolute">
    <origin rpy="0 0 0" xyz="-0.035 0 -0.3179" />
    <parent link="R_hip_yaw_link" />
    <child link="R_knee_pitch_link" />
    <axis xyz="0 1 0" />
    <limit effort="210" lower="0.09" upper="2.478" velocity="10.47" />
  </joint>
  <link name="R_ankle_pitch_link">
    <inertial>
      <origin rpy="0 0 0" xyz="0.00012374 0.00221434 -0.0057231" />
      <mass value="0.11058391" />
      <inertia ixx="2.571E-05" ixy="3E-08" ixz="8E-08" iyy="3.443E-05" iyz="-1.4E-06" izz="4.678E-05" />
    </inertial>
    <visual>
      <origin rpy="0 0 0" xyz="0 0 0" />
      <geometry>
        <mesh filename="../meshes/R_ankle_pitch_link.STL" />
      </geometry>
      <material name="">
        <color rgba="0.627450980392157 0.627450980392157 0.627450980392157 1" />
      </material>
    </visual>
  </link>
  <joint name="R_ankle_pitch_joint" type="revolute">
    <origin rpy="0 0 0" xyz="0 0 -0.410000000000008" />
    <parent link="R_knee_pitch_link" />
    <child link="R_ankle_pitch_link" />
    <axis xyz="0 1 0" />
    <limit effort="60" lower="-1.012" upper="0.488" velocity="12.57" />
  </joint>
  <link name="R_ankle_roll_link">
    <inertial>
      <origin rpy="0 0 0" xyz="0.03406324 2.02E-06 -0.020996" />
      <mass value="0.82687057" />
      <inertia ixx="0.00099158" ixy="-1.9E-07" ixz="0.0002988" iyy="0.00442435" iyz="-2E-08" izz="0.00489724" />
    </inertial>
    <visual>
      <origin rpy="0 0 0" xyz="0 0 0" />
      <geometry>
        <mesh filename="../meshes/R_ankle_roll_link.STL" />
      </geometry>
      <material name="">
        <color rgba="0.698039215686274 0.698039215686274 0.698039215686274 1" />
      </material>
    </visual>
    <collision>
      <origin xyz="0.05 0 -0.035" rpy="0 0 0" />
      <geometry>
        <box size="0.26 0.11 0.03" />
      </geometry>
    </collision>
  </link>
  <joint name="R_ankle_roll_joint" type="revolute">
    <origin rpy="0 0 0" xyz="0 0 -0.0120000000000001" />
    <parent link="R_ankle_pitch_link" />
    <child link="R_ankle_roll_link" />
    <axis xyz="1 0 0" />
    <limit effort="60" lower="-0.401" upper="0.401" velocity="12.57" />
  </joint>
  <joint name="R_foot_ft_joint" type="fixed">
    <origin rpy="0 0 0" xyz="0 0 0" />
    <parent link="R_ankle_roll_link" />
    <child link="R_foot_ft_link" />
  </joint>
  <link name="R_foot_ft_link">
    <inertial>
      <mass value="0.00005" />
      <origin rpy="0 0 0" xyz="0 0 0" />
      <inertia ixx="5e-11" ixy="0" ixz="0" iyy="5e-11" iyz="0" izz="1e-10" />
    </inertial>
    <visual>
      <origin rpy="0 0 0" xyz="0 0 0" />
      <geometry>
        <cylinder length="0.01" radius="0.01" />
      </geometry>
    </visual>
    <material name="orange">
      <color rgba="255 108 10 255" />
    </material>
  </link>
  <ft_sensor name="R_foot_ft">
    <parent link="R_ankle_roll_link" />
    <origin rpy="0 0 0" xyz="0 0 0" />
  </ft_sensor>
  <link name="L_arm_base_link">
    <inertial>
      <origin rpy="0 0 0" xyz="0 0 0" />
      <mass value="0.0001" />
      <inertia ixx="1e-10" ixy="0" ixz="0" iyy="1e-10" iyz="0" izz="1e-10" />
    </inertial>
  </link>
  <joint name="L_arm_base_joint" type="fixed">
    <origin rpy="0.174532925199404 0 0" xyz="0.0 0.114261537495599 0.0" />
    <parent link="torso_link" />
    <child link="L_arm_base_link" />
    <axis xyz="0 0 1" />
  </joint>
  <link name="L_shoulder_pitch_link">
    <inertial>
      <origin rpy="0 0 0" xyz="0.00379496 0.04690286 -4.625E-05" />
      <mass value="0.79842185" />
      <inertia ixx="0.00053576" ixy="-1.098E-05" ixz="-2.52E-06" iyy="0.00048497" iyz="5.49E-06" izz="0.00056322" />
    </inertial>
    <visual>
      <origin rpy="0 0 0" xyz="0 0 0" />
      <geometry>
        <mesh filename="../meshes/L_shoulder_pitch_link.STL" />
      </geometry>
      <material name="">
        <color rgba="0.909803921568627 0.443137254901961 0.0313725490196078 1" />
      </material>
    </visual>
  </link>
  <joint name="L_shoulder_pitch_joint" type="revolute">
    <origin rpy="0 0 0" xyz="0 0 0" />
    <parent link="L_arm_base_link" />
    <child link="L_shoulder_pitch_link" />
    <axis xyz="0 1 0" />
    <limit effort="60" lower="-3.089" upper="2.565" velocity="13.61" />
  </joint>
  <link name="L_shoulder_roll_link">
    <inertial>
      <origin rpy="0 0 0" xyz="0.00388223 0.00090177 -0.08144232" />
      <mass value="0.95445238" />
      <inertia ixx="0.00164727" ixy="7.19E-06" ixz="-0.00025056" iyy="0.00173441" iyz="-6.456E-05" izz="0.00083765" />
    </inertial>
    <visual>
      <origin rpy="0 0 0" xyz="0 0 0" />
      <geometry>
        <mesh filename="../meshes/L_shoulder_roll_link.STL" />
      </geometry>
      <material name="">
        <color rgba="1 1 1 1" />
      </material>
    </visual>
  </link>
  <joint name="L_shoulder_roll_joint" type="revolute">
    <origin rpy="0 0 0" xyz="0 0.0499000000000001 0" />
    <parent link="L_shoulder_pitch_link" />
    <child link="L_shoulder_roll_link" />
    <axis xyz="1 0 0" />
    <limit effort="60" lower="-0.139" upper="1.884" velocity="13.61" />
  </joint>
  <link name="L_shoulder_yaw_link">
    <inertial>
      <origin rpy="0 0 0" xyz="-0.00111624 -0.00509191 -0.07778589" />
      <mass value="0.95157552" />
      <inertia ixx="0.00135197" ixy="2.72E-06" ixz="2.03E-05" iyy="0.00136425" iyz="-6.158E-05" izz="0.0006392" />
    </inertial>
    <visual>
      <origin rpy="0 0 0" xyz="0 0 0" />
      <geometry>
        <mesh filename="../meshes/L_shoulder_yaw_link.STL" />
      </geometry>
      <material name="">
        <color rgba="0.698039215686274 0.698039215686274 0.698039215686274 1" />
      </material>
    </visual>
    <collision>
      <origin xyz="0 0 -0.0115" rpy="0 0 0" />
      <geometry>
        <cylinder length="0.177" radius="0.04" />
      </geometry>
    </collision>
  </link>
  <joint name="L_shoulder_yaw_joint" type="revolute">
    <origin rpy="0 0 0" xyz="0 0 -0.126749998384828" />
    <parent link="L_shoulder_roll_link" />
    <child link="L_shoulder_yaw_link" />
    <axis xyz="0 0 1" />
    <limit effort="25" lower="-2.844" upper="2.844" velocity="13.61" />
  </joint>
  <link name="L_elbow_pitch_link">
    <inertial>
      <origin rpy="0 0 0" xyz="-0.00109585 -0.00301164 -0.08162983" />
      <mass value="0.91030288" />
      <inertia ixx="0.0015001" ixy="-7.5E-07" ixz="6.414E-05" iyy="0.00142992" iyz="0.00019571" izz="0.00073744" />
    </inertial>
    <visual>
      <origin rpy="0 0 0" xyz="0 0 0" />
      <geometry>
        <mesh filename="../meshes/L_elbow_pitch_link.STL" />
      </geometry>
      <material name="">
        <color rgba="0.909803921568627 0.443137254901961 0.0313725490196078 1" />
      </material>
    </visual>
  </link>
  <joint name="L_elbow_pitch_joint" type="revolute">
    <origin rpy="0 0 0" xyz="0 0 -0.0932499981849194" />
    <parent link="L_shoulder_yaw_link" />
    <child link="L_elbow_pitch_link" />
    <axis xyz="0 1 0" />
    <limit effort="25" lower="-2.2689" upper="0.104" velocity="13.61" />
  </joint>
  <link name="L_elbow_yaw_link">
    <inertial>
      <origin rpy="0 0 0" xyz="0.00041996 0.00835103 -0.0205441" />
      <mass value="0.09233082" />
      <inertia ixx="8.165E-05" ixy="1.5E-07" ixz="6.7E-07" iyy="6.775E-05" iyz="1.273E-05" izz="7.884E-05" />
    </inertial>
    <visual>
      <origin rpy="0 0 0" xyz="0 0 0" />
      <geometry>
        <mesh filename="../meshes/L_elbow_yaw_link.STL" />
      </geometry>
      <material name="">
        <color rgba="1 1 1 1" />
      </material>
    </visual>
    <collision>
      <origin xyz="0 0 -0.008" rpy="0 0 0" />
      <geometry>
        <cylinder length="0.056" radius="0.035" />
      </geometry>
    </collision>
  </link>
  <joint name="L_elbow_yaw_joint" type="revolute">
    <origin rpy="0 0 0" xyz="0 0 -0.124250001797163" />
    <parent link="L_elbow_pitch_link" />
    <child link="L_elbow_yaw_link" />
    <axis xyz="0 0 1" />
    <limit effort="25" lower="-2.844" upper="2.844" velocity="13.61" />
  </joint>
  <link name="L_wrist_pitch_link">
    <inertial>
      <origin rpy="0 0 0" xyz="0.00244378 0.00252389 -0.01940281" />
      <mass value="0.49823595" />
      <inertia ixx="0.00032853" ixy="3.17E-06" ixz="2.818E-05" iyy="0.00033198" iyz="-2.391E-05" izz="0.00017354" />
    </inertial>
    <visual>
      <origin rpy="0 0 0" xyz="0 0 0" />
      <geometry>
        <mesh filename="../meshes/L_wrist_pitch_link.STL" />
      </geometry>
      <material name="">
        <color rgba="0.898039215686275 0.917647058823529 0.929411764705882 1" />
      </material>
    </visual>
  </link>
  <joint name="L_wrist_pitch_joint" type="revolute">
    <origin rpy="0 0 0" xyz="0 0 -0.05575" />
    <parent link="L_elbow_yaw_link" />
    <child link="L_wrist_pitch_link" />
    <axis xyz="0 1 0" />
    <limit effort="6" lower="-0.68" upper="0.68" velocity="12.57" />
  </joint>
  <link name="L_wrist_roll_link">
    <inertial>
      <origin rpy="0 0 0" xyz="0.0085537 -1.437E-05 -0.02191296" />
      <mass value="0.04766635" />
      <inertia ixx="2.225E-05" ixy="0" ixz="-7.71E-06" iyy="4.753E-05" iyz="0" izz="3.827E-05" />
    </inertial>
    <visual>
      <origin rpy="0 0 0" xyz="0 0 0" />
      <geometry>
        <mesh filename="../meshes/L_wrist_roll_link.STL" />
      </geometry>
      <material name="">
        <color rgba="1 1 1 1" />
      </material>
    </visual>
    <collision>
      <origin xyz="0 0 -0.045" rpy="0 0 0" />
      <geometry>
        <box size="0.08 0.025 0.12" />
      </geometry>
    </collision>
  </link>
  <link name="L_hand_link">
    <inertial>
      <origin xyz="0.0 0.0 0.04" rpy="0 0 0" />
      <mass value="0.4" />
      <inertia ixx="0.0003" iyy="0.0004" izz="0.00015" ixy="0" ixz="0" iyz="0" />
    </inertial>
    <visual>
      <origin xyz="0.0 0 0" rpy="0 -1.57 0" />
      <geometry>
        <mesh filename="../meshes/left_rubber_hand.STL" />
      </geometry>
      <material name="white">
        <color rgba="1 1 1 1" />
      </material>
    </visual>
  </link>
  <joint name="L_hand_joint" type="fixed">
    <parent link="L_wrist_roll_link" />
    <child link="L_hand_link" />
    <origin xyz="0.0 0 -0.04" rpy="0 3.14159 0" />
  </joint>
  <joint name="L_wrist_roll_joint" type="revolute">
    <origin rpy="0 0 0" xyz="0 0 -0.0399515014686295" />
    <parent link="L_wrist_pitch_link" />
    <child link="L_wrist_roll_link" />
    <axis xyz="1 0 0" />
    <limit effort="6" lower="-1.57" upper="1.57" velocity="12.57" />
  </joint>
  <link name="R_arm_base_link">
    <inertial>
      <origin rpy="0 0 0" xyz="0 0 0" />
      <mass value="0.0001" />
      <inertia ixx="1e-10" ixy="0" ixz="0" iyy="1e-10" iyz="0" izz="1e-10" />
    </inertial>
  </link>
  <joint name="R_arm_base_joint" type="fixed">
    <origin rpy="-0.174532925199405 0 0" xyz="0.0 -0.114809942431709 0.0" />
    <parent link="torso_link" />
    <child link="R_arm_base_link" />
    <axis xyz="0 0 1" />
  </joint>
  <link name="R_shoulder_pitch_link">
    <inertial>
      <origin rpy="0 0 0" xyz="0.00384148 -0.046973 7.92E-06" />
      <mass value="0.79994046" />
      <inertia ixx="0.00053607" ixy="6.43E-06" ixz="-2.4E-07" iyy="0.00048679" iyz="-5.14E-06" izz="0.00056359" />
    </inertial>
    <visual>
      <origin rpy="0 0 0" xyz="0 0 0" />
      <geometry>
        <mesh filename="../meshes/R_shoulder_pitch_link.STL" />
      </geometry>
      <material name="">
        <color rgba="0.909803921568627 0.443137254901961 0.0313725490196078 1" />
      </material>
    </visual>
  </link>
  <joint name="R_shoulder_pitch_joint" type="revolute">
    <origin rpy="0 0 0" xyz="0 0 0" />
    <parent link="R_arm_base_link" />
    <child link="R_shoulder_pitch_link" />
    <axis xyz="0 1 0" />
    <limit effort="60" lower="-3.089" upper="2.565" velocity="13.61" />
  </joint>
  <link name="R_shoulder_roll_link">
    <inertial>
      <origin rpy="0 0 0" xyz="0.00374986 -0.00090026 -0.08145595" />
      <mass value="0.95418329" />
      <inertia ixx="0.00164607" ixy="-7.42E-06" ixz="-0.00024807" iyy="0.00173406" iyz="6.443E-05" izz="0.00083829" />
    </inertial>
    <visual>
      <origin rpy="0 0 0" xyz="0 0 0" />
      <geometry>
        <mesh filename="../meshes/R_shoulder_roll_link.STL" />
      </geometry>
      <material name="">
        <color rgba="0.909803921568627 0.443137254901961 0.0313725490196078 1" />
      </material>
    </visual>
  </link>
  <joint name="R_shoulder_roll_joint" type="revolute">
    <origin rpy="0 0 0" xyz="0 -0.0499 0" />
    <parent link="R_shoulder_pitch_link" />
    <child link="R_shoulder_roll_link" />
    <axis xyz="1 0 0" />
    <limit effort="60" lower="-1.884" upper="0.139" velocity="13.61" />
  </joint>
  <link name="R_shoulder_yaw_link">
    <inertial>
      <origin rpy="0 0 0" xyz="-0.00111484 -0.00508263 -0.07767727" />
      <mass value="0.95271279" />
      <inertia ixx="0.00135945" ixy="2.71E-06" ixz="2.018E-05" iyy="0.00137161" iyz="-6.206E-05" izz="0.00063937" />
    </inertial>
    <visual>
      <origin rpy="0 0 0" xyz="0 0 0" />
      <geometry>
        <mesh filename="../meshes/R_shoulder_yaw_link.STL" />
      </geometry>
      <material name="">
        <color rgba="0.698039215686274 0.698039215686274 0.698039215686274 1" />
      </material>
    </visual>
    <collision>
      <origin xyz="0 0 -0.0115" rpy="0 0 0" />
      <geometry>
        <cylinder length="0.177" radius="0.04" />
      </geometry>
    </collision>
  </link>
  <joint name="R_shoulder_yaw_joint" type="revolute">
    <origin rpy="0 0 0" xyz="0 0 -0.126750000099661" />
    <parent link="R_shoulder_roll_link" />
    <child link="R_shoulder_yaw_link" />
    <axis xyz="0 0 1" />
    <limit effort="25" lower="-2.844" upper="2.844" velocity="13.61" />
  </joint>
  <link name="R_elbow_pitch_link">
    <inertial>
      <origin rpy="0 0 0" xyz="-0.00109585 -0.00301164 -0.08162983" />
      <mass value="0.91030288" />
      <inertia ixx="0.00150011" ixy="-7.5E-07" ixz="6.414E-05" iyy="0.00142992" iyz="0.00019571" izz="0.00073744" />
    </inertial>
    <visual>
      <origin rpy="0 0 0" xyz="0 0 0" />
      <geometry>
        <mesh filename="../meshes/R_elbow_pitch_link.STL" />
      </geometry>
      <material name="">
        <color rgba="0.909803921568627 0.443137254901961 0.0313725490196078 1" />
      </material>
    </visual>
  </link>
  <joint name="R_elbow_pitch_joint" type="revolute">
    <origin rpy="0 0 0" xyz="0 0 -0.0932499981849196" />
    <parent link="R_shoulder_yaw_link" />
    <child link="R_elbow_pitch_link" />
    <axis xyz="0 1 0" />
    <limit effort="25" lower="-2.2689" upper="0.104" velocity="13.61" />
  </joint>
  <link name="R_elbow_yaw_link">
    <inertial>
      <origin rpy="0 0 0" xyz="0.00042308 0.00819376 -0.0202823" />
      <mass value="0.09164929" />
      <inertia ixx="8.047E-05" ixy="1.4E-07" ixz="6.8E-07" iyy="6.686E-05" iyz="1.222E-05" izz="7.851E-05" />
    </inertial>
    <visual>
      <origin rpy="0 0 0" xyz="0 0 0" />
      <geometry>
        <mesh filename="../meshes/R_elbow_yaw_link.STL" />
      </geometry>
      <material name="">
        <color rgba="1 1 1 1" />
      </material>
    </visual>
    <collision>
      <origin xyz="0 0 -0.008" rpy="0 0 0" />
      <geometry>
        <cylinder length="0.056" radius="0.035" />
      </geometry>
    </collision>
  </link>
  <joint name="R_elbow_yaw_joint" type="revolute">
    <origin rpy="0 0 0" xyz="0 0 -0.124250001797163" />
    <parent link="R_elbow_pitch_link" />
    <child link="R_elbow_yaw_link" />
    <axis xyz="0 0 1" />
    <limit effort="25" lower="-2.844" upper="2.844" velocity="13.61" />
  </joint>
  <link name="R_wrist_pitch_link">
    <inertial>
      <origin rpy="0 0 0" xyz="0.00244378 0.00252389 -0.01940281" />
      <mass value="0.49823595" />
      <inertia ixx="0.00032853" ixy="3.17E-06" ixz="2.818E-05" iyy="0.00033198" iyz="-2.391E-05" izz="0.00017354" />
    </inertial>
    <visual>
      <origin rpy="0 0 0" xyz="0 0 0" />
      <geometry>
        <mesh filename="../meshes/R_wrist_pitch_link.STL" />
      </geometry>
      <material name="">
        <color rgba="0.647058823529412 1 0.529411764705882 1" />
      </material>
    </visual>
  </link>
  <joint name="R_wrist_pitch_joint" type="revolute">
    <origin rpy="0 0 0" xyz="0 0 -0.05575" />
    <parent link="R_elbow_yaw_link" />
    <child link="R_wrist_pitch_link" />
    <axis xyz="0 1 0" />
    <limit effort="6" lower="-0.68" upper="0.68" velocity="12.57" />
  </joint>
  <link name="R_wrist_roll_link">
    <inertial>
      <origin rpy="0 0 0" xyz="0.0085537 -1.437E-05 -0.02191296" />
      <mass value="0.04766635" />
      <inertia ixx="2.225E-05" ixy="0" ixz="-7.71E-06" iyy="4.753E-05" iyz="0" izz="3.827E-05" />
    </inertial>
    <visual>
      <origin rpy="0 0 0" xyz="0 0 0" />
      <geometry>
        <mesh filename="../meshes/R_wrist_roll_link.STL" />
      </geometry>
      <material name="">
        <color rgba="1 1 1 1" />
      </material>
    </visual>
    <collision>
      <origin xyz="0 0 -0.045" rpy="0 0 0" />
      <geometry>
        <box size="0.08 0.025 0.12" />
      </geometry>
    </collision>
  </link>
  <joint name="R_wrist_roll_joint" type="revolute">
    <origin rpy="0 0 0" xyz="0 0 -0.0399515014686294" />
    <parent link="R_wrist_pitch_link" />
    <child link="R_wrist_roll_link" />
    <axis xyz="1 0 0" />
    <limit effort="6" lower="-1.57" upper="1.57" velocity="12.57" />
  </joint>
  <link name="R_hand_link">
    <inertial>
      <origin xyz="0.0 0.00 0.04" rpy="0 0 0" />
      <mass value="0.4" />
      <inertia ixx="0.0003" iyy="0.0004" izz="0.00015" ixy="0" ixz="0" iyz="0" />
    </inertial>
    <visual>
      <origin xyz="0.0 0 0" rpy="0 -1.57 0" />
      <geometry>
        <mesh filename="../meshes/right_rubber_hand.STL" />
      </geometry>
      <material name="white">
        <color rgba="1 1 1 1" />
      </material>
    </visual>
  </link>
  <joint name="R_hand_joint" type="fixed">
    <parent link="R_wrist_roll_link" />
    <child link="R_hand_link" />
    <origin xyz="0 0 -0.04" rpy="0 3.14159 0" />
  </joint>
</robot>